Workbook

Sheet Dashboard
A1: Shaar Binyamin Gym — Cash-First Owner Dashboard
A2: Focus: what actually comes into the bank, what actually leaves, ending cash and debt. EBITDA, depreciation and DSCR remain in the detail tabs but are intentionally demoted here.
A4: Cash position & key levers
A5: Cash after build + VAT refund | B5: ='Startup & Funding'!B22 -> 160869.73 | C5: Cash reserve target | D5: =Inputs!B80 -> 150000 | E5: Opening debt | F5: =Inputs!B9+Inputs!B10 -> 1140000
A6: Lowest post-opening cash — current base | B6: =IFERROR(__xludf.DUMMYFUNCTION("MIN(FILTER('Owner Pay'!Z21:Z83,'Owner Pay'!C21:C83>0))"),126843.9333898304) -> 126843.93 | C6: Debt-free operating month — current base | D6: ='Owner Pay'!B9 -> 42 | E6: Normal monthly debt payment after grace | F6: =Financing!D10 -> 20881.221
A7: Year 1 modeled cash collected | B7: ='5-Year Summary'!B7 -> 998544 | C7: Year 1 net cash generated | D7: ='5-Year Summary'!B12 -> -10869.73 | E7: Year 1 ending bank cash | F7: ='5-Year Summary'!B14 -> 150000
A8: Year 5 ending bank cash | B8: ='5-Year Summary'!F14 -> 1802390.8 | C8: Year 5 debt remaining | D8: ='5-Year Summary'!F15 -> 0 | E8: Year 5 cash above reserve | F8: =MAX(0,'5-Year Summary'!F14-Inputs!B80) -> 1652390.8
A9: Owner payroll after debt-free | B9: ='Owner Pay'!B12 -> 24000 | C9: Current base owner-pay policy | D9: Debt-Max | E9: Alternative owner-pay scenarios | F9: See Salary Scenarios tab
A11: 5-Year Cash In / Cash Out
A12: Operating year | B12: Cash in — modeled collections | C12: Operating cash out | D12: Debt paid | E12: Tax paid | F12: Owner payroll | G12: Total cash out | H12: Net cash generated | I12: Ending bank cash | J12: Debt remaining | K12: End members
A13: Year 1 | B13: ='5-Year Summary'!B7 -> 998544 | C13: =B13-'5-Year Summary'!B9 -> 927747.25 | D13: ='5-Year Summary'!B10 -> 81666.476 | E13: ='5-Year Summary'!B11 -> 0 | F13: ='5-Year Summary'!B20 -> 0 | G13: =SUM(C13:F13) -> 1009413.7 | H13: =B13-G13 -> -10869.73 | I13: ='5-Year Summary'!B14 -> 150000 | J13: ='5-Year Summary'!B15 -> 1068862.7 | K13: ='5-Year Summary'!B6 -> 450
A14: Year 2 | B14: ='5-Year Summary'!C7 -> 1500294 | C14: =B14-'5-Year Summary'!C9 -> 1008537.5 | D14: ='5-Year Summary'!C10 -> 424218.24 | E14: ='5-Year Summary'!C11 -> 67538.255 | F14: ='5-Year Summary'!C20 -> 0 | G14: =SUM(C14:F14) -> 1500294 | H14: =B14-G14 -> 0 | I14: ='5-Year Summary'!C14 -> 150000 | J14: ='5-Year Summary'!C15 -> 679457.94 | K14: ='5-Year Summary'!C6 -> 600
A15: Year 3 | B15: ='5-Year Summary'!D7 -> 1864899 | C15: =B15-'5-Year Summary'!D9 -> 1067245.1 | D15: ='5-Year Summary'!D10 -> 636626.7 | E15: ='5-Year Summary'!D11 -> 161027.21 | F15: ='5-Year Summary'!D20 -> 0 | G15: =SUM(C15:F15) -> 1864899 | H15: =B15-G15 -> 0 | I15: ='5-Year Summary'!D14 -> 150000 | J15: ='5-Year Summary'!D15 -> 58610.857 | K15: ='5-Year Summary'!D6 -> 725
A16: Year 4 | B16: ='5-Year Summary'!E7 -> 2127147 | C16: =B16-'5-Year Summary'!E9 -> 1109471.5 | D16: ='5-Year Summary'!E10 -> 58610.857 | E16: ='5-Year Summary'!E11 -> 215261.49 | F16: ='5-Year Summary'!E20 -> 0 | G16: =SUM(C16:F16) -> 1383343.8 | H16: =B16-G16 -> 743803.18 | I16: ='5-Year Summary'!E14 -> 893803.18 | J16: ='5-Year Summary'!E15 -> 0 | K16: ='5-Year Summary'!E6 -> 800
A17: Year 5 | B17: ='5-Year Summary'!F7 -> 2291498 | C17: =B17-'5-Year Summary'!F9 -> 1135934.8 | D17: ='5-Year Summary'!F10 -> 0 | E17: ='5-Year Summary'!F11 -> 246975.66 | F17: ='5-Year Summary'!F20 -> 0 | G17: =SUM(C17:F17) -> 1382910.4 | H17: =B17-G17 -> 908587.57 | I17: ='5-Year Summary'!F14 -> 1802390.8 | J17: ='5-Year Summary'!F15 -> 0 | K17: ='5-Year Summary'!F6 -> 850
A18: Cash in is gross modeled collections. Operating cash out is the day-to-day gym cash cost, card fees and net VAT effect; debt, corporate tax and owner payroll are shown separately. This table is designed to reconcile cash in minus cash out to net cash generated.
A20: Owner-pay choices — cash impact
A21: Current base | B21: Debt-Max — no owner salary until debt-free; ₪10k gross each after. | C21: Debt-free op month | D21: ='Salary Scenarios'!B13 -> 42 | E21: Lowest post-opening cash | F21: ='Salary Scenarios'!B27 -> 126843.93
A22: Early Balanced | B22: ₪5k gross each from operating month 7; ₪10k each after debt-free. | C22: Debt-free op month | D22: ='Salary Scenarios'!E13 -> 47 | E22: Lowest post-opening cash | F22: ='Salary Scenarios'!E27 -> 89793.066
A23: Debt sweep rule | B23: Keep the ₪150k reserve target; every 6 months from operating month 12, use excess cash for a lump-sum debt payment.
A24: Distributions | B24: No automatic distributions. Cash stays in the company unless the owners decide otherwise after debt and reserve needs are considered.
A45: Readiness checklist before signing / opening
A46: Item | B46: Status | C46: Why it matters
A47: Bank confirms early-prepayment rules / fees | B47: OPEN | C47: Critical to debt-first plan; model assumes extra payments can be made.
A48: Final insurance quote for rebuilt gym | B48: OPEN | C48: Current ₪600/month may not carry over after rebuild.
A49: Lease assignment, term & rent escalation | B49: OPEN | C49: Major fixed-cost and exit-risk item.
A50: Contractor budget + 3-month closure timeline | B50: OPEN | C50: Directly affects runway and VAT-refund timing.
A51: Retention / presale plan for 317 members | B51: OPEN | C51: Reopening-member assumption is a major early risk.
A52: Moatza agreement terms in writing | B52: OPEN | C52: Currently modeled as an assumption, not signed revenue.
A53: Eurotec quote / final machine list / Smith machine | B53: OPEN | C53: Locks capex and avoids equipment-scope surprises.
A54: Studio instructor payroll vs invoicing status | B54: OPEN | C54: Changes VAT and employer-cost treatment.
A55: Accountant sign-off on salary / dividend policy | B55: OPEN | C55: Personal tax and National Insurance are outside this company model.
A56: Maintenance / equipment-refresh reserve policy | B56: OPEN | C56: Prevents mature-year cash from overstating distributable money.

Sheet Inputs
A1: Shaar Binyamin Gym - Core Inputs
A2: Simple operating assumptions for the 5-year model. Blue cells are editable; yellow cells are the few assumptions worth revisiting.
A4: Financing, VAT & tax
A5: Input | B5: Value | C5: Unit | D5: Treatment | E5: Source | F5: Status
A6: VAT rate | B6: 0.18 | C6: % | D6: Gross prices/invoices normalized to ex-VAT for P&L. | E6: User / source docs | F6: Given
A7: Partner 1 ownership | B7: 0.5 | C7: % | D7: Assumed 50/50 equity. | E7: User | F7: Assumption
A8: Partner 2 ownership | B8: =1-B7 -> 0.5 | C8: % | D8: Formula = 100% - Partner 1. | E8: Formula | F8: Formula
A9: Loan A - interest free | B9: 240000 | C9: NIS | D9: 0%; no interest/no payments during grace; 60 payments after grace. | E9: User | F9: Given
A10: Loan B - Prime | B10: 900000 | C10: NIS | D10: Prime-linked; no interest/no payments during grace; 60 amortizing payments after grace. | E10: User | F10: Given
A11: BOI policy rate | B11: 0.0325 | C11: % | D11: Effective 03/09/2026. | E11: Bank of Israel 01/09/2026 | F11: Current
A12: Prime spread | B12: 0.015 | C12: % | D12: Prime = BOI rate + 1.5%. | E12: Israeli Prime convention | F12: Current
A13: Current Prime rate | B13: =B11+B12 -> 0.0475 | C13: % | D13: Formula. | E13: Formula | F13: Formula
A15: Grace months from funding | B15: 12 | C15: months | D15: Build months consume part of grace. | E15: User + Claude timeline | F15: Important
A16: Repayment term after grace | B16: 60 | C16: months | D16: 5 years after grace. | E16: User | F16: Given
A17: Corporate tax rate | B17: 0.23 | C17: % | D17: Simplified monthly accrual with tax-loss carryforward. | E17: gym_dump.md | F17: Model
A18: Monthly depreciation | B18: 6813 | C18: NIS / month | D18: Tax deduction only; non-cash. | E18: gym_dump.md | F18: Model
A19: Operating cost inflation | B19: 0 | C19: % / year | D19: 0% base to match Claude current settings. | E19: Model choice | F19: Assumption
A20: Membership price inflation | B20: 0 | C20: % / year | D20: 0% base to match Claude current settings. | E20: Model choice | F20: Assumption
A22: Current business / reopening assumptions
A23: Input | B23: Value | C23: Unit | D23: Treatment | E23: Source | F23: Status
A24: Current active paying members | B24: 317 | C24: members | D24: Verified Aug 2026. | E24: gym_dump.md | F24: Verified
A25: Planning capacity | B25: 850 | C25: members | D25: Base planning cap for the forecast. | E25: User update | F25: Target
A26: Current blended fee actually collected | B26: 206 | C26: NIS gross / month | D26: Reality check only. | E26: gym_dump.md | F26: Verified
A27: Closure period | B27: 3 | C27: months | D27: Full renovation closure. | E27: gym_dump.md | F27: Assumption
A28: Retention at reopening | B28: 0.75 | C28: % of current | D28: 75% gives ~238; consistent with user's ~250. | E28: gym_dump.md | F28: Assumption
A29: Average monthly increase to Year-1 target | B29: =(B70-ROUND(B24*B28,0))/11 -> 19.272727 | C29: members / month | D29: Calculated from reopening members to the Year-1 target. | E29: Model | F29: Formula
A30: Year 1 end member goal (linked below) | B30: =B70 -> 450 | C30: members | D30: Edit the target in the Membership growth targets section below. | E30: Formula | F30: Formula
A33: Closure-period fixed cash cost | B33: 22000 | C33: NIS gross / month | D33: Approx. 20,018 ex-VAT. | E33: gym_dump.md | F33: Model
A34: Closure-period economic cost | B34: 20018 | C34: NIS ex VAT / month | D34: Use in P&L/cash model; source dump selected monthly build cost. | E34: gym_dump.md | F34: Model
A36: Membership products & other revenue
A37: Input | B37: Value | C37: Unit | D37: Treatment | E37: Source | F37: Status
A38: Full access - gym + classes | B38: 230 | C38: NIS gross / month | D38: Main product; classes have direct revenue role. | E38: User + consultant | F38: Given
A39: Single service - gym OR classes | B39: 200 | C39: NIS gross / month | D39: Lower tier. | E39: User | F39: Assumption
A40: Soldier / student program | B40: 150 | C40: NIS gross / month | D40: Discount tier. | E40: User + consultant | F40: Given
A41: Full-access mix | B41: 0.85 | C41: % members | D41: Most members at full price. | E41: User direction | F41: Assumption
A42: Single-service mix | B42: 0.1 | C42: % members | D42: Editable. | E42: Model assumption | F42: Assumption
A43: Soldier mix | B43: 0.05 | C43: % members | D43: Low percentage. | E43: User direction | F43: Assumption
A44: Blended membership fee | B44: =B38*B41+B39*B42+B40*B43 -> 223 | C44: NIS gross / month | D44: Weighted formula. | E44: Formula | F44: Formula
A45: Existing partnerships gross | B45: 8160 | C45: NIS / month | D45: Prefit + Mob tie-ins. | E45: gym_dump.md | F45: Verified
A46: Existing store/day passes gross | B46: 1580 | C46: NIS / month | D46: Current actual. | E46: gym_dump.md | F46: Verified
...

Sheet Operating Costs
A1: Rebuild Monthly Operating Cost - Transparent VAT Build
A2: Monthly operating plan using morning human coverage, automated evenings/weekends, outsourced cleaning and scheduled studio classes.
A4: Category | B4: Line item | C4: Gross cash / mo | D4: VATable? | E4: VAT cash | F4: Ex-VAT cost | G4: Model note | H4: Source | I4: Confidence
A5: Fixed | B5: Rent | C5: 20000 | D5: Y | E5: =IF(D5="Y",C5-C5/(1+Inputs!$B$6),0) -> 3050.8475 | F5: =C5-E5 -> 16949.153 | G5: Incl VAT; user confirmed | H5: gym_dump.md | I5: Base
A6: Fixed | B6: Arnona | C6: 4500 | D6: N | E6: =IF(D6="Y",C6-C6/(1+Inputs!$B$6),0) -> 0 | F6: =C6-E6 -> 4500 | G6: Claude operating model | H6: gym_dump.md | I6: Base
A7: Fixed | B7: Electricity | C7: 4000 | D7: Y | E7: =IF(D7="Y",C7-C7/(1+Inputs!$B$6),0) -> 610.16949 | F7: =C7-E7 -> 3389.8305 | G7: Claude operating model | H7: gym_dump.md | I7: Base
A8: Fixed | B8: Water | C8: 1500 | D8: Y | E8: =IF(D8="Y",C8-C8/(1+Inputs!$B$6),0) -> 228.81356 | F8: =C8-E8 -> 1271.1864 | G8: Claude operating model | H8: gym_dump.md | I8: Base
A9: Fixed | B9: Cleaning - outsourced | C9: 3500 | D9: Y | E9: =IF(D9="Y",C9-C9/(1+Inputs!$B$6),0) -> 533.89831 | F9: =C9-E9 -> 2966.1017 | G9: Outsourced cleaning allowance | H9: gym_dump.md | I9: Base
A10: Fixed | B10: Accounting | C10: 1800 | D10: Y | E10: =IF(D10="Y",C10-C10/(1+Inputs!$B$6),0) -> 274.57627 | F10: =C10-E10 -> 1525.4237 | G10: Monthly accounting allowance | H10: gym_dump.md | I10: Base
A11: Fixed | B11: Software / CRM / access | C11: 1500 | D11: Y | E11: =IF(D11="Y",C11-C11/(1+Inputs!$B$6),0) -> 228.81356 | F11: =C11-E11 -> 1271.1864 | G11: Automated access stack | H11: gym_dump.md | I11: Base
A12: Fixed | B12: Phone + mobile + comms | C12: 1059 | D12: Y | E12: =IF(D12="Y",C12-C12/(1+Inputs!$B$6),0) -> 161.54237 | F12: =C12-E12 -> 897.45763 | G12: Claude operating model | H12: gym_dump.md | I12: Base
A13: Fixed | B13: Maintenance | C13: 1000 | D13: Y | E13: =IF(D13="Y",C13-C13/(1+Inputs!$B$6),0) -> 152.54237 | F13: =C13-E13 -> 847.45763 | G13: Allowance | H13: gym_dump.md | I13: Base
A14: Fixed | B14: Insurance | C14: 600 | D14: N | E14: =IF(D14="Y",C14-C14/(1+Inputs!$B$6),0) -> 0 | F14: =C14-E14 -> 600 | G14: Current actual; re-quote rebuilt facility | H14: gym_dump.md | I14: Base
A15: Fixed | B15: Office / signage / sundries | C15: 250 | D15: Y | E15: =IF(D15="Y",C15-C15/(1+Inputs!$B$6),0) -> 38.135593 | F15: =C15-E15 -> 211.86441 | G15: Allowance | H15: gym_dump.md | I15: Base
A16: Fixed | B16: Management fee | C16: 2300 | D16: Y | E16: =IF(D16="Y",C16-C16/(1+Inputs!$B$6),0) -> 350.84746 | F16: =C16-E16 -> 1949.1525 | G16: Confirmed real | H16: gym_dump.md | I16: Base
... A19: Marketing | B19: Ongoing marketing | C19: 2000 | D19: Y | E19: =IF(D19="Y",C19-C19/(1+Inputs!$B$6),0) -> 305.08475 | F19: =C19-E19 -> 1694.9153 | G19: Recurring | H19: gym_dump.md | I19: Base
A21: Monthly totals
A22: Metric | B22: Gross | C22: Ex-VAT | D22: Comment
A23: Core monthly operating cost | B23: =SUM(C5:C19) -> 69849 | C23: =SUM(F5:F19) -> 63913.729 | D23: Before variable card processing
A24: Card processing at ₪100k gross billings | B24: 1000 | C24: =B24/(1+Inputs!$B$6) -> 847.45763 | D24: 1% example
A25: Total at ₪100k gross billings | B25: =B23+B24 -> 70849 | C25: =C23+C24 -> 64761.186 | D25: Illustrative run-rate
A26: Annual core operating cost | B26: =B23*12 -> 838188 | C26: =C23*12 -> 766964.75 | D26: Before variable card processing
A30: Open items
A31: Insurance | B31: ₪600 is the current actual; obtain a fresh quote for the rebuilt facility.
A32: Studio VAT | B32: Studio instruction is treated conservatively as non-VAT until contractor status is confirmed.
A33: Automation | B33: Base model assumes automated entry and no permanent evening/weekend front desk.
A34: Owner salary | B34: Owner salaries are excluded here and tested separately on the Owner Pay tab.

Sheet Startup & Funding
A1: Startup Investment, VAT & Working Capital
A2: The ₪75k run-in amount is treated as working-capital reserve rather than a separate VATable capital invoice.
A4: Startup item | B4: Ex-VAT amount | C4: VATable? | D4: VAT | E4: Gross cash | F4: Base treatment | G4: Source | H4: Note
A5: Business plan | B5: 9000 | C5: Y | D5: =IF(C5="Y",B5*Inputs!$B$6,0) -> 1620 | E5: =B5+D5 -> 10620 | F5: Upfront | G5: Consultant
A6: Plans & consultants | B6: 90000 | C6: Y | D6: =IF(C6="Y",B6*Inputs!$B$6,0) -> 16200 | E6: =B6+D6 -> 106200 | F6: Upfront | G6: Consultant
A7: Build / renovation | B7: 200000 | C7: Y | D7: =IF(C7="Y",B7*Inputs!$B$6,0) -> 36000 | E7: =B7+D7 -> 236000 | F7: Upfront | G7: Consultant
A8: Operational equipment | B8: 146000 | C8: Y | D8: =IF(C8="Y",B8*Inputs!$B$6,0) -> 26280 | E8: =B8+D8 -> 172280 | F8: Upfront | G8: Consultant
A9: Professional gym equipment | B9: 399076.27 | C9: Y | D9: =IF(C9="Y",B9*Inputs!$B$6,0) -> 71833.729 | E9: =B9+D9 -> 470910 | F9: Upfront | G9: Eurotec quote | H9: Exact quote
A10: Run-in reserve | B10: 75000 | C10: N | D10: =IF(C10="Y",B10*Inputs!$B$6,0) -> 0 | E10: =B10+D10 -> 75000 | F10: Working-capital reserve | G10: Consultant | H10: Not VATable invoice in base
A11: Optional extra presale marketing | B11: =Inputs!$B$62 -> 0 | C11: Y | D11: =IF(C11="Y",B11*Inputs!$B$6,0) -> 0 | E11: =B11+D11 -> 0 | F11: Only if activated | G11: Inputs | H11: Base zero
A13: Base normalized funding bridge
A14: Metric | B14: Amount
A15: Total startup budget ex VAT incl reserve | B15: =SUM(B5:B11) -> 919076.27
A16: Reclaimable startup VAT | B16: =SUM(D5:D11) -> 151933.73
A17: Gross cash allocated incl reserve | B17: =SUM(E5:E11) -> 1071010
A18: Total financing | B18: =Inputs!$B$9+Inputs!$B$10 -> 1140000
A19: Cash headroom at funding | B19: =B18-B17 -> 68990.001
A20: 3-month closure economic cost exVAT | B20: =Inputs!$B$27*Inputs!$B$34 -> 60054
A21: Build VAT refund | B21: =B16 -> 151933.73
A22: Approx cash after closure + refund | B22: =B19-B20+B21 -> 160869.73

Sheet Financing
A1: Loan Schedule
A2: 12 months from funding with no payment and no interest; the 3-month renovation period uses part of that grace.
A4: Metric | B4: Loan A | C4: Loan B | D4: Total
A5: Principal | B5: =Inputs!$B$9 -> 240000 | C5: =Inputs!$B$10 -> 900000 | D5: =SUM(B5:C5) -> 1140000
A6: Annual rate | B6: 0 | C6: =Inputs!$B$13 -> 0.0475
A7: Grace months | B7: =Inputs!$B$15 -> 12 | C7: =Inputs!$B$15 -> 12
A8: Balance after grace | B8: =B5 -> 240000 | C8: =C5 -> 900000
A9: Repayment months | B9: 60 | C9: 60
A10: Monthly payment after grace | B10: =B8/B9 -> 4000 | C10: =C8*(C6/12)/(1-(1+C6/12)^(-C9)) -> 16881.221 | D10: =SUM(B10:C10) -> 20881.221
A11: Total debt service after grace | D11: =D10 -> 20881.221
A12: Payment starts timeline month | D12: =Inputs!$B$15 -> 12
A13: Approx operating month payment starts | D13: =MAX(1,Inputs!$B$15-Inputs!$B$27+1) -> 10
A15: 63-Month funding timeline loan schedule
A16: Timeline Mo | B16: A Opening | C16: A Interest | D16: A Payment | E16: A Closing | F16: B Opening | G16: B Interest | H16: B Payment | I16: B Closing | J16: Total Payment
A17: 0 | B17: =$B$5 -> 240000 | C17: 0 | D17: 0 | E17: =$B$5 -> 240000 | F17: =$C$5 -> 900000 | G17: 0 | H17: 0 | I17: =$C$5 -> 900000 | J17: 0
A18: =A17+1 -> 1 | B18: =E17 -> 240000 | C18: =0 -> 0 | D18: =IF(A18<Inputs!$B$15,0,MIN($B$10,B18)) -> 0 | E18: =MAX(0,B18-D18) -> 240000 | F18: =I17 -> 900000 | G18: =IF(A18<Inputs!$B$15,0,F18*$C$6/12) -> 0 | H18: =IF(A18<Inputs!$B$15,0,MIN($C$10,F18+G18)) -> 0 | I18: =MAX(0,F18+G18-H18) -> 900000 | J18: =D18+H18 -> 0
A19: =A18+1 -> 2 | B19: =E18 -> 240000 | C19: =0 -> 0 | D19: =IF(A19<Inputs!$B$15,0,MIN($B$10,B19)) -> 0 | E19: =MAX(0,B19-D19) -> 240000 | F19: =I18 -> 900000 | G19: =IF(A19<Inputs!$B$15,0,F19*$C$6/12) -> 0 | H19: =IF(A19<Inputs!$B$15,0,MIN($C$10,F19+G19)) -> 0 | I19: =MAX(0,F19+G19-H19) -> 900000 | J19: =D19+H19 -> 0
A20: =A19+1 -> 3 | B20: =E19 -> 240000 | C20: =0 -> 0 | D20: =IF(A20<Inputs!$B$15,0,MIN($B$10,B20)) -> 0 | E20: =MAX(0,B20-D20) -> 240000 | F20: =I19 -> 900000 | G20: =IF(A20<Inputs!$B$15,0,F20*$C$6/12) -> 0 | H20: =IF(A20<Inputs!$B$15,0,MIN($C$10,F20+G20)) -> 0 | I20: =MAX(0,F20+G20-H20) -> 900000 | J20: =D20+H20 -> 0
A21: =A20+1 -> 4 | B21: =E20 -> 240000 | C21: =0 -> 0 | D21: =IF(A21<Inputs!$B$15,0,MIN($B$10,B21)) -> 0 | E21: =MAX(0,B21-D21) -> 240000 | F21: =I20 -> 900000 | G21: =IF(A21<Inputs!$B$15,0,F21*$C$6/12) -> 0 | H21: =IF(A21<Inputs!$B$15,0,MIN($C$10,F21+G21)) -> 0 | I21: =MAX(0,F21+G21-H21) -> 900000 | J21: =D21+H21 -> 0
A22: =A21+1 -> 5 | B22: =E21 -> 240000 | C22: =0 -> 0 | D22: =IF(A22<Inputs!$B$15,0,MIN($B$10,B22)) -> 0 | E22: =MAX(0,B22-D22) -> 240000 | F22: =I21 -> 900000 | G22: =IF(A22<Inputs!$B$15,0,F22*$C$6/12) -> 0 | H22: =IF(A22<Inputs!$B$15,0,MIN($C$10,F22+G22)) -> 0 | I22: =MAX(0,F22+G22-H22) -> 900000 | J22: =D22+H22 -> 0
A23: =A22+1 -> 6 | B23: =E22 -> 240000 | C23: =0 -> 0 | D23: =IF(A23<Inputs!$B$15,0,MIN($B$10,B23)) -> 0 | E23: =MAX(0,B23-D23) -> 240000 | F23: =I22 -> 900000 | G23: =IF(A23<Inputs!$B$15,0,F23*$C$6/12) -> 0 | H23: =IF(A23<Inputs!$B$15,0,MIN($C$10,F23+G23)) -> 0 | I23: =MAX(0,F23+G23-H23) -> 900000 | J23: =D23+H23 -> 0
A24: =A23+1 -> 7 | B24: =E23 -> 240000 | C24: =0 -> 0 | D24: =IF(A24<Inputs!$B$15,0,MIN($B$10,B24)) -> 0 | E24: =MAX(0,B24-D24) -> 240000 | F24: =I23 -> 900000 | G24: =IF(A24<Inputs!$B$15,0,F24*$C$6/12) -> 0 | H24: =IF(A24<Inputs!$B$15,0,MIN($C$10,F24+G24)) -> 0 | I24: =MAX(0,F24+G24-H24) -> 900000 | J24: =D24+H24 -> 0
A25: =A24+1 -> 8 | B25: =E24 -> 240000 | C25: =0 -> 0 | D25: =IF(A25<Inputs!$B$15,0,MIN($B$10,B25)) -> 0 | E25: =MAX(0,B25-D25) -> 240000 | F25: =I24 -> 900000 | G25: =IF(A25<Inputs!$B$15,0,F25*$C$6/12) -> 0 | H25: =IF(A25<Inputs!$B$15,0,MIN($C$10,F25+G25)) -> 0 | I25: =MAX(0,F25+G25-H25) -> 900000 | J25: =D25+H25 -> 0
A26: =A25+1 -> 9 | B26: =E25 -> 240000 | C26: =0 -> 0 | D26: =IF(A26<Inputs!$B$15,0,MIN($B$10,B26)) -> 0 | E26: =MAX(0,B26-D26) -> 240000 | F26: =I25 -> 900000 | G26: =IF(A26<Inputs!$B$15,0,F26*$C$6/12) -> 0 | H26: =IF(A26<Inputs!$B$15,0,MIN($C$10,F26+G26)) -> 0 | I26: =MAX(0,F26+G26-H26) -> 900000 | J26: =D26+H26 -> 0
A27: =A26+1 -> 10 | B27: =E26 -> 240000 | C27: =0 -> 0 | D27: =IF(A27<Inputs!$B$15,0,MIN($B$10,B27)) -> 0 | E27: =MAX(0,B27-D27) -> 240000 | F27: =I26 -> 900000 | G27: =IF(A27<Inputs!$B$15,0,F27*$C$6/12) -> 0 | H27: =IF(A27<Inputs!$B$15,0,MIN($C$10,F27+G27)) -> 0 | I27: =MAX(0,F27+G27-H27) -> 900000 | J27: =D27+H27 -> 0
A28: =A27+1 -> 11 | B28: =E27 -> 240000 | C28: =0 -> 0 | D28: =IF(A28<Inputs!$B$15,0,MIN($B$10,B28)) -> 0 | E28: =MAX(0,B28-D28) -> 240000 | F28: =I27 -> 900000 | G28: =IF(A28<Inputs!$B$15,0,F28*$C$6/12) -> 0 | H28: =IF(A28<Inputs!$B$15,0,MIN($C$10,F28+G28)) -> 0 | I28: =MAX(0,F28+G28-H28) -> 900000 | J28: =D28+H28 -> 0
A29: =A28+1 -> 12 | B29: =E28 -> 240000 | C29: =0 -> 0 | D29: =IF(A29<Inputs!$B$15,0,MIN($B$10,B29)) -> 4000 | E29: =MAX(0,B29-D29) -> 236000 | F29: =I28 -> 900000 | G29: =IF(A29<Inputs!$B$15,0,F29*$C$6/12) -> 3562.5 | H29: =IF(A29<Inputs!$B$15,0,MIN($C$10,F29+G29)) -> 16881.221 | I29: =MAX(0,F29+G29-H29) -> 886681.28 | J29: =D29+H29 -> 20881.221
... A79: =A78+1 -> 62 | B79: =E78 -> 40000 | C79: =0 -> 0 | D79: =IF(A79<Inputs!$B$15,0,MIN($B$10,B79)) -> 4000 | E79: =MAX(0,B79-D79) -> 36000 | F79: =I78 -> 165194.48 | G79: =IF(A79<Inputs!$B$15,0,F79*$C$6/12) -> 653.8948 | H79: =IF(A79<Inputs!$B$15,0,MIN($C$10,F79+G79)) -> 16881.221 | I79: =MAX(0,F79+G79-H79) -> 148967.15 | J79: =D79+H79 -> 20881.221

Sheet Monthly Base
A1: 63-Month Base Cash Model - 3 Build Months + 60 Operating Months
A2: Membership follows the editable Year 1-5 targets on Inputs. Monthly values interpolate automatically between targets, while pricing, costs, financing, VAT and owner-pay assumptions flow through the full model.
A4: Timeline Mo | B4: Phase | C4: Operating Mo | D4: Organic Members | E4: Organic Billed | F4: Moatza Members | G4: Total Members | H4: Blended Organic Fee | I4: Membership Gross | J4: Other Gross | K4: Total Gross Billings | L4: Net Revenue ex VAT | M4: Card Fees ex VAT | N4: Core Opex ex VAT | O4: EBITDA | P4: Debt Service | Q4: Loan B Interest | R4: Depreciation | S4: Taxable Before Loss | T4: Tax Loss CF Begin | U4: Taxable After Loss | V4: Corp Tax | W4: Tax Loss CF End | X4: Pre-Owner Cash | Y4: Startup VAT Refund | Z4: Cash Balance | AA4: Debt Balance | AB4: Op BE Members | AC4: Post-Debt BE Members | AD4: Notes
A5: 0 | B5: =IF(A5<Inputs!$B$27,"BUILD","OPEN") -> BUILD | C5: =IF(B5="OPEN",A5-Inputs!$B$27+1,0) -> 0 | D5: =IF(C5=0,0,MIN(Inputs!$B$25,IF(C5=1,ROUND(Inputs!$B$24*Inputs!$B$28,0),IF(C5<=12,ROUND(ROUND(Inputs!$B$24*Inputs!$B$28,0)+(Inputs!$B$70-ROUND(Inputs!$B$24*Inputs!$B$28,0))*(C5-1)/11,0),IF(C5<=24,ROUND(Inputs!$B$70+(Inputs!$B$71-Inputs!$B$70)*(C5-12)/12,0),IF(C5<=36,ROUND(Inputs!$B$71+(Inputs!$B$72-Inputs!$B$71)*(C5-24)/12,0),IF(C5<=48,ROUND(Inputs!$B$72+(Inputs!$B$73-Inputs!$B$72)*(C5-36)/12,0),ROUND(Inputs!$B$73+(Inputs!$B$74-Inputs!$B$73)*MIN(C5-48,12)/12,0)))))))) -> 0 | E5: =IF(C5=0,0,IF(Inputs!$B$50=1,MIN(D5,MAX(0,Inputs!$B$57-Inputs!$B$54)),MIN(D5,Inputs!$B$57))) -> 0 | F5: =IF(AND(C5>=Inputs!$B$56,Inputs!$B$50=1),Inputs!$B$54,0) -> 0 | G5: =E5+F5 -> 0 | H5: =Inputs!$B$44*(1+Inputs!$B$20)^MAX(0,ROUNDUP(C5/12,0)-1) -> 223 | I5: =IF(C5=0,0,E5*H5+F5*Inputs!$B$55) -> 0 | J5: =IF(C5=0,0,Inputs!$B$47) -> 0 | K5: =I5+J5 -> 0 | L5: =K5/(1+Inputs!$B$6) -> 0 | M5: =(K5*Inputs!$B$49)/(1+Inputs!$B$6) -> 0 | N5: =IF(C5=0,Inputs!$B$34,'Operating Costs'!$C$23*(1+Inputs!$B$19)^MAX(0,ROUNDUP(C5/12,0)-1)) -> 20018 | O5: =L5-M5-N5 -> -20018 | P5: =Financing!J17 -> 0 | Q5: =Financing!G17 -> 0 | R5: =IF(C5=0,0,Inputs!$B$18) -> 0 | S5: =O5-R5-Q5 -> -20018 | T5: 0 | U5: =MAX(0,S5-T5) -> 0 | V5: =U5*Inputs!$B$17 -> 0 | W5: =MAX(0,T5-MAX(0,S5))+MAX(0,-S5) -> 20018 | X5: =O5-P5-V5 -> -20018 | Y5: =IF(A5=Inputs!$B$63,'Startup & Funding'!$B$16,0) -> 0 | Z5: ='Startup & Funding'!$B$19+X5+Y5 -> 48972.001 | AA5: =Financing!E17+Financing!I17 -> 1140000 | AB5: =('Operating Costs'!$C$23-(Inputs!$B$47*(1-Inputs!$B$49)/(1+Inputs!$B$6)))/(Inputs!$B$44*(1-Inputs!$B$49)/(1+Inputs!$B$6)) -> 312.46637 | AC5: =('Operating Costs'!$C$23+Financing!$D$10-(Inputs!$B$47*(1-Inputs!$B$49)/(1+Inputs!$B$6)))/(Inputs!$B$44*(1-Inputs!$B$49)/(1+Inputs!$B$6)) -> 424.07501 | AD5: Funding month 0
A6: =A5+1 -> 1 | B6: =IF(A6<Inputs!$B$27,"BUILD","OPEN") -> BUILD | C6: =IF(B6="OPEN",A6-Inputs!$B$27+1,0) -> 0 | D6: =IF(C6=0,0,MIN(Inputs!$B$25,IF(C6=1,ROUND(Inputs!$B$24*Inputs!$B$28,0),IF(C6<=12,ROUND(ROUND(Inputs!$B$24*Inputs!$B$28,0)+(Inputs!$B$70-ROUND(Inputs!$B$24*Inputs!$B$28,0))*(C6-1)/11,0),IF(C6<=24,ROUND(Inputs!$B$70+(Inputs!$B$71-Inputs!$B$70)*(C6-12)/12,0),IF(C6<=36,ROUND(Inputs!$B$71+(Inputs!$B$72-Inputs!$B$71)*(C6-24)/12,0),IF(C6<=48,ROUND(Inputs!$B$72+(Inputs!$B$73-Inputs!$B$72)*(C6-36)/12,0),ROUND(Inputs!$B$73+(Inputs!$B$74-Inputs!$B$73)*MIN(C6-48,12)/12,0)))))))) -> 0 | E6: =IF(C6=0,0,IF(Inputs!$B$50=1,MIN(D6,MAX(0,Inputs!$B$57-Inputs!$B$54)),MIN(D6,Inputs!$B$57))) -> 0 | F6: =IF(AND(C6>=Inputs!$B$56,Inputs!$B$50=1),Inputs!$B$54,0) -> 0 | G6: =E6+F6 -> 0 | H6: =Inputs!$B$44*(1+Inputs!$B$20)^MAX(0,ROUNDUP(C6/12,0)-1) -> 223 | I6: =IF(C6=0,0,E6*H6+F6*Inputs!$B$55) -> 0 | J6: =IF(C6=0,0,Inputs!$B$47) -> 0 | K6: =I6+J6 -> 0 | L6: =K6/(1+Inputs!$B$6) -> 0 | M6: =(K6*Inputs!$B$49)/(1+Inputs!$B$6) -> 0 | N6: =IF(C6=0,Inputs!$B$34,'Operating Costs'!$C$23*(1+Inputs!$B$19)^MAX(0,ROUNDUP(C6/12,0)-1)) -> 20018 | O6: =L6-M6-N6 -> -20018 | P6: {=INDEX(Financing!$J$17:$J$79,A6+1)} -> 0 | Q6: {=INDEX(Financing!$G$17:$G$79,A6+1)} -> 0 | R6: =IF(C6=0,0,Inputs!$B$18) -> 0 | S6: =O6-R6-Q6 -> -20018 | T6: =W5 -> 20018 | U6: =MAX(0,S6-T6) -> 0 | V6: =U6*Inputs!$B$17 -> 0 | W6: =MAX(0,T6-MAX(0,S6))+MAX(0,-S6) -> 40036 | X6: =O6-P6-V6 -> -20018 | Y6: =IF(A6=Inputs!$B$63,'Startup & Funding'!$B$16,0) -> 0 | Z6: =Z5+X6+Y6 -> 28954.001 | AA6: {=INDEX(Financing!$E$17:$E$79,A6+1)+INDEX(Financing!$I$17:$I$79,A6+1)} -> 1140000 | AB6: =AB5 -> 312.46637 | AC6: =AC5 -> 424.07501 | AD6: =IF(C6=1,"REOPEN",IF(A6=Inputs!$B$15,"DEBT START",IF(AND(C6>0,MOD(C6,12)=0),"YEAR END","")))
A7: =A6+1 -> 2 | B7: =IF(A7<Inputs!$B$27,"BUILD","OPEN") -> BUILD | C7: =IF(B7="OPEN",A7-Inputs!$B$27+1,0) -> 0 | D7: =IF(C7=0,0,MIN(Inputs!$B$25,IF(C7=1,ROUND(Inputs!$B$24*Inputs!$B$28,0),IF(C7<=12,ROUND(ROUND(Inputs!$B$24*Inputs!$B$28,0)+(Inputs!$B$70-ROUND(Inputs!$B$24*Inputs!$B$28,0))*(C7-1)/11,0),IF(C7<=24,ROUND(Inputs!$B$70+(Inputs!$B$71-Inputs!$B$70)*(C7-12)/12,0),IF(C7<=36,ROUND(Inputs!$B$71+(Inputs!$B$72-Inputs!$B$71)*(C7-24)/12,0),IF(C7<=48,ROUND(Inputs!$B$72+(Inputs!$B$73-Inputs!$B$72)*(C7-36)/12,0),ROUND(Inputs!$B$73+(Inputs!$B$74-Inputs!$B$73)*MIN(C7-48,12)/12,0)))))))) -> 0 | E7: =IF(C7=0,0,IF(Inputs!$B$50=1,MIN(D7,MAX(0,Inputs!$B$57-Inputs!$B$54)),MIN(D7,Inputs!$B$57))) -> 0 | F7: =IF(AND(C7>=Inputs!$B$56,Inputs!$B$50=1),Inputs!$B$54,0) -> 0 | G7: =E7+F7 -> 0 | H7: =Inputs!$B$44*(1+Inputs!$B$20)^MAX(0,ROUNDUP(C7/12,0)-1) -> 223 | I7: =IF(C7=0,0,E7*H7+F7*Inputs!$B$55) -> 0 | J7: =IF(C7=0,0,Inputs!$B$47) -> 0 | K7: =I7+J7 -> 0 | L7: =K7/(1+Inputs!$B$6) -> 0 | M7: =(K7*Inputs!$B$49)/(1+Inputs!$B$6) -> 0 | N7: =IF(C7=0,Inputs!$B$34,'Operating Costs'!$C$23*(1+Inputs!$B$19)^MAX(0,ROUNDUP(C7/12,0)-1)) -> 20018 | O7: =L7-M7-N7 -> -20018 | P7: {=INDEX(Financing!$J$17:$J$79,A7+1)} -> 0 | Q7: {=INDEX(Financing!$G$17:$G$79,A7+1)} -> 0 | R7: =IF(C7=0,0,Inputs!$B$18) -> 0 | S7: =O7-R7-Q7 -> -20018 | T7: =W6 -> 40036 | U7: =MAX(0,S7-T7) -> 0 | V7: =U7*Inputs!$B$17 -> 0 | W7: =MAX(0,T7-MAX(0,S7))+MAX(0,-S7) -> 60054 | X7: =O7-P7-V7 -> -20018 | Y7: =IF(A7=Inputs!$B$63,'Startup & Funding'!$B$16,0) -> 151933.73 | Z7: =Z6+X7+Y7 -> 160869.73 | AA7: {=INDEX(Financing!$E$17:$E$79,A7+1)+INDEX(Financing!$I$17:$I$79,A7+1)} -> 1140000 | AB7: =AB6 -> 312.46637 | AC7: =AC6 -> 424.07501 | AD7: =IF(C7=1,"REOPEN",IF(A7=Inputs!$B$15,"DEBT START",IF(AND(C7>0,MOD(C7,12)=0),"YEAR END","")))
A8: =A7+1 -> 3 | B8: =IF(A8<Inputs!$B$27,"BUILD","OPEN") -> OPEN | C8: =IF(B8="OPEN",A8-Inputs!$B$27+1,0) -> 1 | D8: =IF(C8=0,0,MIN(Inputs!$B$25,IF(C8=1,ROUND(Inputs!$B$24*Inputs!$B$28,0),IF(C8<=12,ROUND(ROUND(Inputs!$B$24*Inputs!$B$28,0)+(Inputs!$B$70-ROUND(Inputs!$B$24*Inputs!$B$28,0))*(C8-1)/11,0),IF(C8<=24,ROUND(Inputs!$B$70+(Inputs!$B$71-Inputs!$B$70)*(C8-12)/12,0),IF(C8<=36,ROUND(Inputs!$B$71+(Inputs!$B$72-Inputs!$B$71)*(C8-24)/12,0),IF(C8<=48,ROUND(Inputs!$B$72+(Inputs!$B$73-Inputs!$B$72)*(C8-36)/12,0),ROUND(Inputs!$B$73+(Inputs!$B$74-Inputs!$B$73)*MIN(C8-48,12)/12,0)))))))) -> 238 | E8: =IF(C8=0,0,IF(Inputs!$B$50=1,MIN(D8,MAX(0,Inputs!$B$57-Inputs!$B$54)),MIN(D8,Inputs!$B$57))) -> 238 | F8: =IF(AND(C8>=Inputs!$B$56,Inputs!$B$50=1),Inputs!$B$54,0) -> 0 | G8: =E8+F8 -> 238 | H8: =Inputs!$B$44*(1+Inputs!$B$20)^MAX(0,ROUNDUP(C8/12,0)-1) -> 223 | I8: =IF(C8=0,0,E8*H8+F8*Inputs!$B$55) -> 53074 | J8: =IF(C8=0,0,Inputs!$B$47) -> 6500 | K8: =I8+J8 -> 59574 | L8: =K8/(1+Inputs!$B$6) -> 50486.441 | M8: =(K8*Inputs!$B$49)/(1+Inputs!$B$6) -> 504.86441 | N8: =IF(C8=0,Inputs!$B$34,'Operating Costs'!$C$23*(1+Inputs!$B$19)^MAX(0,ROUNDUP(C8/12,0)-1)) -> 63913.729 | O8: =L8-M8-N8 -> -13932.153 | P8: {=INDEX(Financing!$J$17:$J$79,A8+1)} -> 0 | Q8: {=INDEX(Financing!$G$17:$G$79,A8+1)} -> 0 | R8: =IF(C8=0,0,Inputs!$B$18) -> 6813 | S8: =O8-R8-Q8 -> -20745.153 | T8: =W7 -> 60054 | U8: =MAX(0,S8-T8) -> 0 | V8: =U8*Inputs!$B$17 -> 0 | W8: =MAX(0,T8-MAX(0,S8))+MAX(0,-S8) -> 80799.153 | X8: =O8-P8-V8 -> -13932.153 | Y8: =IF(A8=Inputs!$B$63,'Startup & Funding'!$B$16,0) -> 0 | Z8: =Z7+X8+Y8 -> 146937.58 | AA8: {=INDEX(Financing!$E$17:$E$79,A8+1)+INDEX(Financing!$I$17:$I$79,A8+1)} -> 1140000 | AB8: =AB7 -> 312.46637 | AC8: =AC7 -> 424.07501 | AD8: =IF(C8=1,"REOPEN",IF(A8=Inputs!$B$15,"DEBT START",IF(AND(C8>0,MOD(C8,12)=0),"YEAR END",""))) -> REOPEN
A9: =A8+1 -> 4 | B9: =IF(A9<Inputs!$B$27,"BUILD","OPEN") -> OPEN | C9: =IF(B9="OPEN",A9-Inputs!$B$27+1,0) -> 2 | D9: =IF(C9=0,0,MIN(Inputs!$B$25,IF(C9=1,ROUND(Inputs!$B$24*Inputs!$B$28,0),IF(C9<=12,ROUND(ROUND(Inputs!$B$24*Inputs!$B$28,0)+(Inputs!$B$70-ROUND(Inputs!$B$24*Inputs!$B$28,0))*(C9-1)/11,0),IF(C9<=24,ROUND(Inputs!$B$70+(Inputs!$B$71-Inputs!$B$70)*(C9-12)/12,0),IF(C9<=36,ROUND(Inputs!$B$71+(Inputs!$B$72-Inputs!$B$71)*(C9-24)/12,0),IF(C9<=48,ROUND(Inputs!$B$72+(Inputs!$B$73-Inputs!$B$72)*(C9-36)/12,0),ROUND(Inputs!$B$73+(Inputs!$B$74-Inputs!$B$73)*MIN(C9-48,12)/12,0)))))))) -> 257 | E9: =IF(C9=0,0,IF(Inputs!$B$50=1,MIN(D9,MAX(0,Inputs!$B$57-Inputs!$B$54)),MIN(D9,Inputs!$B$57))) -> 257 | F9: =IF(AND(C9>=Inputs!$B$56,Inputs!$B$50=1),Inputs!$B$54,0) -> 0 | G9: =E9+F9 -> 257 | H9: =Inputs!$B$44*(1+Inputs!$B$20)^MAX(0,ROUNDUP(C9/12,0)-1) -> 223 | I9: =IF(C9=0,0,E9*H9+F9*Inputs!$B$55) -> 57311 | J9: =IF(C9=0,0,Inputs!$B$47) -> 6500 | K9: =I9+J9 -> 63811 | L9: =K9/(1+Inputs!$B$6) -> 54077.119 | M9: =(K9*Inputs!$B$49)/(1+Inputs!$B$6) -> 540.77119 | N9: =IF(C9=0,Inputs!$B$34,'Operating Costs'!$C$23*(1+Inputs!$B$19)^MAX(0,ROUNDUP(C9/12,0)-1)) -> 63913.729 | O9: =L9-M9-N9 -> -10377.381 | P9: {=INDEX(Financing!$J$17:$J$79,A9+1)} -> 0 | Q9: {=INDEX(Financing!$G$17:$G$79,A9+1)} -> 0 | R9: =IF(C9=0,0,Inputs!$B$18) -> 6813 | S9: =O9-R9-Q9 -> -17190.381 | T9: =W8 -> 80799.153 | U9: =MAX(0,S9-T9) -> 0 | V9: =U9*Inputs!$B$17 -> 0 | W9: =MAX(0,T9-MAX(0,S9))+MAX(0,-S9) -> 97989.534 | X9: =O9-P9-V9 -> -10377.381 | Y9: =IF(A9=Inputs!$B$63,'Startup & Funding'!$B$16,0) -> 0 | Z9: =Z8+X9+Y9 -> 136560.2 | AA9: {=INDEX(Financing!$E$17:$E$79,A9+1)+INDEX(Financing!$I$17:$I$79,A9+1)} -> 1140000 | AB9: =AB8 -> 312.46637 | AC9: =AC8 -> 424.07501 | AD9: =IF(C9=1,"REOPEN",IF(A9=Inputs!$B$15,"DEBT START",IF(AND(C9>0,MOD(C9,12)=0),"YEAR END","")))
A10: =A9+1 -> 5 | B10: =IF(A10<Inputs!$B$27,"BUILD","OPEN") -> OPEN | C10: =IF(B10="OPEN",A10-Inputs!$B$27+1,0) -> 3 | D10: =IF(C10=0,0,MIN(Inputs!$B$25,IF(C10=1,ROUND(Inputs!$B$24*Inputs!$B$28,0),IF(C10<=12,ROUND(ROUND(Inputs!$B$24*Inputs!$B$28,0)+(Inputs!$B$70-ROUND(Inputs!$B$24*Inputs!$B$28,0))*(C10-1)/11,0),IF(C10<=24,ROUND(Inputs!$B$70+(Inputs!$B$71-Inputs!$B$70)*(C10-12)/12,0),IF(C10<=36,ROUND(Inputs!$B$71+(Inputs!$B$72-Inputs!$B$71)*(C10-24)/12,0),IF(C10<=48,ROUND(Inputs!$B$72+(Inputs!$B$73-Inputs!$B$72)*(C10-36)/12,0),ROUND(Inputs!$B$73+(Inputs!$B$74-Inputs!$B$73)*MIN(C10-48,12)/12,0)))))))) -> 277 | E10: =IF(C10=0,0,IF(Inputs!$B$50=1,MIN(D10,MAX(0,Inputs!$B$57-Inputs!$B$54)),MIN(D10,Inputs!$B$57))) -> 277 | F10: =IF(AND(C10>=Inputs!$B$56,Inputs!$B$50=1),Inputs!$B$54,0) -> 0 | G10: =E10+F10 -> 277 | H10: =Inputs!$B$44*(1+Inputs!$B$20)^MAX(0,ROUNDUP(C10/12,0)-1) -> 223 | I10: =IF(C10=0,0,E10*H10+F10*Inputs!$B$55) -> 61771 | J10: =IF(C10=0,0,Inputs!$B$47) -> 6500 | K10: =I10+J10 -> 68271 | L10: =K10/(1+Inputs!$B$6) -> 57856.78 | M10: =(K10*Inputs!$B$49)/(1+Inputs!$B$6) -> 578.5678 | N10: =IF(C10=0,Inputs!$B$34,'Operating Costs'!$C$23*(1+Inputs!$B$19)^MAX(0,ROUNDUP(C10/12,0)-1)) -> 63913.729 | O10: =L10-M10-N10 -> -6635.5169 | P10: {=INDEX(Financing!$J$17:$J$79,A10+1)} -> 0 | Q10: {=INDEX(Financing!$G$17:$G$79,A10+1)} -> 0 | R10: =IF(C10=0,0,Inputs!$B$18) -> 6813 | S10: =O10-R10-Q10 -> -13448.517 | T10: =W9 -> 97989.534 | U10: =MAX(0,S10-T10) -> 0 | V10: =U10*Inputs!$B$17 -> 0 | W10: =MAX(0,T10-MAX(0,S10))+MAX(0,-S10) -> 111438.05 | X10: =O10-P10-V10 -> -6635.5169 | Y10: =IF(A10=Inputs!$B$63,'Startup & Funding'!$B$16,0) -> 0 | Z10: =Z9+X10+Y10 -> 129924.68 | AA10: {=INDEX(Financing!$E$17:$E$79,A10+1)+INDEX(Financing!$I$17:$I$79,A10+1)} -> 1140000 | AB10: =AB9 -> 312.46637 | AC10: =AC9 -> 424.07501 | AD10: =IF(C10=1,"REOPEN",IF(A10=Inputs!$B$15,"DEBT START",IF(AND(C10>0,MOD(C10,12)=0),"YEAR END","")))
A11: =A10+1 -> 6 | B11: =IF(A11<Inputs!$B$27,"BUILD","OPEN") -> OPEN | C11: =IF(B11="OPEN",A11-Inputs!$B$27+1,0) -> 4 | D11: =IF(C11=0,0,MIN(Inputs!$B$25,IF(C11=1,ROUND(Inputs!$B$24*Inputs!$B$28,0),IF(C11<=12,ROUND(ROUND(Inputs!$B$24*Inputs!$B$28,0)+(Inputs!$B$70-ROUND(Inputs!$B$24*Inputs!$B$28,0))*(C11-1)/11,0),IF(C11<=24,ROUND(Inputs!$B$70+(Inputs!$B$71-Inputs!$B$70)*(C11-12)/12,0),IF(C11<=36,ROUND(Inputs!$B$71+(Inputs!$B$72-Inputs!$B$71)*(C11-24)/12,0),IF(C11<=48,ROUND(Inputs!$B$72+(Inputs!$B$73-Inputs!$B$72)*(C11-36)/12,0),ROUND(Inputs!$B$73+(Inputs!$B$74-Inputs!$B$73)*MIN(C11-48,12)/12,0)))))))) -> 296 | E11: =IF(C11=0,0,IF(Inputs!$B$50=1,MIN(D11,MAX(0,Inputs!$B$57-Inputs!$B$54)),MIN(D11,Inputs!$B$57))) -> 296 | F11: =IF(AND(C11>=Inputs!$B$56,Inputs!$B$50=1),Inputs!$B$54,0) -> 0 | G11: =E11+F11 -> 296 | H11: =Inputs!$B$44*(1+Inputs!$B$20)^MAX(0,ROUNDUP(C11/12,0)-1) -> 223 | I11: =IF(C11=0,0,E11*H11+F11*Inputs!$B$55) -> 66008 | J11: =IF(C11=0,0,Inputs!$B$47) -> 6500 | K11: =I11+J11 -> 72508 | L11: =K11/(1+Inputs!$B$6) -> 61447.458 | M11: =(K11*Inputs!$B$49)/(1+Inputs!$B$6) -> 614.47458 | N11: =IF(C11=0,Inputs!$B$34,'Operating Costs'!$C$23*(1+Inputs!$B$19)^MAX(0,ROUNDUP(C11/12,0)-1)) -> 63913.729 | O11: =L11-M11-N11 -> -3080.7458 | P11: {=INDEX(Financing!$J$17:$J$79,A11+1)} -> 0 | Q11: {=INDEX(Financing!$G$17:$G$79,A11+1)} -> 0 | R11: =IF(C11=0,0,Inputs!$B$18) -> 6813 | S11: =O11-R11-Q11 -> -9893.7458 | T11: =W10 -> 111438.05 | U11: =MAX(0,S11-T11) -> 0 | V11: =U11*Inputs!$B$17 -> 0 | W11: =MAX(0,T11-MAX(0,S11))+MAX(0,-S11) -> 121331.8 | X11: =O11-P11-V11 -> -3080.7458 | Y11: =IF(A11=Inputs!$B$63,'Startup & Funding'!$B$16,0) -> 0 | Z11: =Z10+X11+Y11 -> 126843.93 | AA11: {=INDEX(Financing!$E$17:$E$79,A11+1)+INDEX(Financing!$I$17:$I$79,A11+1)} -> 1140000 | AB11: =AB10 -> 312.46637 | AC11: =AC10 -> 424.07501 | AD11: =IF(C11=1,"REOPEN",IF(A11=Inputs!$B$15,"DEBT START",IF(AND(C11>0,MOD(C11,12)=0),"YEAR END","")))
A12: =A11+1 -> 7 | B12: =IF(A12<Inputs!$B$27,"BUILD","OPEN") -> OPEN | C12: =IF(B12="OPEN",A12-Inputs!$B$27+1,0) -> 5 | D12: =IF(C12=0,0,MIN(Inputs!$B$25,IF(C12=1,ROUND(Inputs!$B$24*Inputs!$B$28,0),IF(C12<=12,ROUND(ROUND(Inputs!$B$24*Inputs!$B$28,0)+(Inputs!$B$70-ROUND(Inputs!$B$24*Inputs!$B$28,0))*(C12-1)/11,0),IF(C12<=24,ROUND(Inputs!$B$70+(Inputs!$B$71-Inputs!$B$70)*(C12-12)/12,0),IF(C12<=36,ROUND(Inputs!$B$71+(Inputs!$B$72-Inputs!$B$71)*(C12-24)/12,0),IF(C12<=48,ROUND(Inputs!$B$72+(Inputs!$B$73-Inputs!$B$72)*(C12-36)/12,0),ROUND(Inputs!$B$73+(Inputs!$B$74-Inputs!$B$73)*MIN(C12-48,12)/12,0)))))))) -> 315 | E12: =IF(C12=0,0,IF(Inputs!$B$50=1,MIN(D12,MAX(0,Inputs!$B$57-Inputs!$B$54)),MIN(D12,Inputs!$B$57))) -> 315 | F12: =IF(AND(C12>=Inputs!$B$56,Inputs!$B$50=1),Inputs!$B$54,0) -> 0 | G12: =E12+F12 -> 315 | H12: =Inputs!$B$44*(1+Inputs!$B$20)^MAX(0,ROUNDUP(C12/12,0)-1) -> 223 | I12: =IF(C12=0,0,E12*H12+F12*Inputs!$B$55) -> 70245 | J12: =IF(C12=0,0,Inputs!$B$47) -> 6500 | K12: =I12+J12 -> 76745 | L12: =K12/(1+Inputs!$B$6) -> 65038.136 | M12: =(K12*Inputs!$B$49)/(1+Inputs!$B$6) -> 650.38136 | N12: =IF(C12=0,Inputs!$B$34,'Operating Costs'!$C$23*(1+Inputs!$B$19)^MAX(0,ROUNDUP(C12/12,0)-1)) -> 63913.729 | O12: =L12-M12-N12 -> 474.02542 | P12: {=INDEX(Financing!$J$17:$J$79,A12+1)} -> 0 | Q12: {=INDEX(Financing!$G$17:$G$79,A12+1)} -> 0 | R12: =IF(C12=0,0,Inputs!$B$18) -> 6813 | S12: =O12-R12-Q12 -> -6338.9746 | T12: =W11 -> 121331.8 | U12: =MAX(0,S12-T12) -> 0 | V12: =U12*Inputs!$B$17 -> 0 | W12: =MAX(0,T12-MAX(0,S12))+MAX(0,-S12) -> 127670.77 | X12: =O12-P12-V12 -> 474.02542 | Y12: =IF(A12=Inputs!$B$63,'Startup & Funding'!$B$16,0) -> 0 | Z12: =Z11+X12+Y12 -> 127317.96 | AA12: {=INDEX(Financing!$E$17:$E$79,A12+1)+INDEX(Financing!$I$17:$I$79,A12+1)} -> 1140000 | AB12: =AB11 -> 312.46637 | AC12: =AC11 -> 424.07501 | AD12: =IF(C12=1,"REOPEN",IF(A12=Inputs!$B$15,"DEBT START",IF(AND(C12>0,MOD(C12,12)=0),"YEAR END","")))
A13: =A12+1 -> 8 | B13: =IF(A13<Inputs!$B$27,"BUILD","OPEN") -> OPEN | C13: =IF(B13="OPEN",A13-Inputs!$B$27+1,0) -> 6 | D13: =IF(C13=0,0,MIN(Inputs!$B$25,IF(C13=1,ROUND(Inputs!$B$24*Inputs!$B$28,0),IF(C13<=12,ROUND(ROUND(Inputs!$B$24*Inputs!$B$28,0)+(Inputs!$B$70-ROUND(Inputs!$B$24*Inputs!$B$28,0))*(C13-1)/11,0),IF(C13<=24,ROUND(Inputs!$B$70+(Inputs!$B$71-Inputs!$B$70)*(C13-12)/12,0),IF(C13<=36,ROUND(Inputs!$B$71+(Inputs!$B$72-Inputs!$B$71)*(C13-24)/12,0),IF(C13<=48,ROUND(Inputs!$B$72+(Inputs!$B$73-Inputs!$B$72)*(C13-36)/12,0),ROUND(Inputs!$B$73+(Inputs!$B$74-Inputs!$B$73)*MIN(C13-48,12)/12,0)))))))) -> 334 | E13: =IF(C13=0,0,IF(Inputs!$B$50=1,MIN(D13,MAX(0,Inputs!$B$57-Inputs!$B$54)),MIN(D13,Inputs!$B$57))) -> 334 | F13: =IF(AND(C13>=Inputs!$B$56,Inputs!$B$50=1),Inputs!$B$54,0) -> 0 | G13: =E13+F13 -> 334 | H13: =Inputs!$B$44*(1+Inputs!$B$20)^MAX(0,ROUNDUP(C13/12,0)-1) -> 223 | I13: =IF(C13=0,0,E13*H13+F13*Inputs!$B$55) -> 74482 | J13: =IF(C13=0,0,Inputs!$B$47) -> 6500 | K13: =I13+J13 -> 80982 | L13: =K13/(1+Inputs!$B$6) -> 68628.814 | M13: =(K13*Inputs!$B$49)/(1+Inputs!$B$6) -> 686.28814 | N13: =IF(C13=0,Inputs!$B$34,'Operating Costs'!$C$23*(1+Inputs!$B$19)^MAX(0,ROUNDUP(C13/12,0)-1)) -> 63913.729 | O13: =L13-M13-N13 -> 4028.7966 | P13: {=INDEX(Financing!$J$17:$J$79,A13+1)} -> 0 | Q13: {=INDEX(Financing!$G$17:$G$79,A13+1)} -> 0 | R13: =IF(C13=0,0,Inputs!$B$18) -> 6813 | S13: =O13-R13-Q13 -> -2784.2034 | T13: =W12 -> 127670.77 | U13: =MAX(0,S13-T13) -> 0 | V13: =U13*Inputs!$B$17 -> 0 | W13: =MAX(0,T13-MAX(0,S13))+MAX(0,-S13) -> 130454.97 | X13: =O13-P13-V13 -> 4028.7966 | Y13: =IF(A13=Inputs!$B$63,'Startup & Funding'!$B$16,0) -> 0 | Z13: =Z12+X13+Y13 -> 131346.76 | AA13: {=INDEX(Financing!$E$17:$E$79,A13+1)+INDEX(Financing!$I$17:$I$79,A13+1)} -> 1140000 | AB13: =AB12 -> 312.46637 | AC13: =AC12 -> 424.07501 | AD13: =IF(C13=1,"REOPEN",IF(A13=Inputs!$B$15,"DEBT START",IF(AND(C13>0,MOD(C13,12)=0),"YEAR END","")))
A14: =A13+1 -> 9 | B14: =IF(A14<Inputs!$B$27,"BUILD","OPEN") -> OPEN | C14: =IF(B14="OPEN",A14-Inputs!$B$27+1,0) -> 7 | D14: =IF(C14=0,0,MIN(Inputs!$B$25,IF(C14=1,ROUND(Inputs!$B$24*Inputs!$B$28,0),IF(C14<=12,ROUND(ROUND(Inputs!$B$24*Inputs!$B$28,0)+(Inputs!$B$70-ROUND(Inputs!$B$24*Inputs!$B$28,0))*(C14-1)/11,0),IF(C14<=24,ROUND(Inputs!$B$70+(Inputs!$B$71-Inputs!$B$70)*(C14-12)/12,0),IF(C14<=36,ROUND(Inputs!$B$71+(Inputs!$B$72-Inputs!$B$71)*(C14-24)/12,0),IF(C14<=48,ROUND(Inputs!$B$72+(Inputs!$B$73-Inputs!$B$72)*(C14-36)/12,0),ROUND(Inputs!$B$73+(Inputs!$B$74-Inputs!$B$73)*MIN(C14-48,12)/12,0)))))))) -> 354 | E14: =IF(C14=0,0,IF(Inputs!$B$50=1,MIN(D14,MAX(0,Inputs!$B$57-Inputs!$B$54)),MIN(D14,Inputs!$B$57))) -> 354 | F14: =IF(AND(C14>=Inputs!$B$56,Inputs!$B$50=1),Inputs!$B$54,0) -> 0 | G14: =E14+F14 -> 354 | H14: =Inputs!$B$44*(1+Inputs!$B$20)^MAX(0,ROUNDUP(C14/12,0)-1) -> 223 | I14: =IF(C14=0,0,E14*H14+F14*Inputs!$B$55) -> 78942 | J14: =IF(C14=0,0,Inputs!$B$47) -> 6500 | K14: =I14+J14 -> 85442 | L14: =K14/(1+Inputs!$B$6) -> 72408.475 | M14: =(K14*Inputs!$B$49)/(1+Inputs!$B$6) -> 724.08475 | N14: =IF(C14=0,Inputs!$B$34,'Operating Costs'!$C$23*(1+Inputs!$B$19)^MAX(0,ROUNDUP(C14/12,0)-1)) -> 63913.729 | O14: =L14-M14-N14 -> 7770.661 | P14: {=INDEX(Financing!$J$17:$J$79,A14+1)} -> 0 | Q14: {=INDEX(Financing!$G$17:$G$79,A14+1)} -> 0 | R14: =IF(C14=0,0,Inputs!$B$18) -> 6813 | S14: =O14-R14-Q14 -> 957.66102 | T14: =W13 -> 130454.97 | U14: =MAX(0,S14-T14) -> 0 | V14: =U14*Inputs!$B$17 -> 0 | W14: =MAX(0,T14-MAX(0,S14))+MAX(0,-S14) -> 129497.31 | X14: =O14-P14-V14 -> 7770.661 | Y14: =IF(A14=Inputs!$B$63,'Startup & Funding'!$B$16,0) -> 0 | Z14: =Z13+X14+Y14 -> 139117.42 | AA14: {=INDEX(Financing!$E$17:$E$79,A14+1)+INDEX(Financing!$I$17:$I$79,A14+1)} -> 1140000 | AB14: =AB13 -> 312.46637 | AC14: =AC13 -> 424.07501 | AD14: =IF(C14=1,"REOPEN",IF(A14=Inputs!$B$15,"DEBT START",IF(AND(C14>0,MOD(C14,12)=0),"YEAR END","")))
A15: =A14+1 -> 10 | B15: =IF(A15<Inputs!$B$27,"BUILD","OPEN") -> OPEN | C15: =IF(B15="OPEN",A15-Inputs!$B$27+1,0) -> 8 | D15: =IF(C15=0,0,MIN(Inputs!$B$25,IF(C15=1,ROUND(Inputs!$B$24*Inputs!$B$28,0),IF(C15<=12,ROUND(ROUND(Inputs!$B$24*Inputs!$B$28,0)+(Inputs!$B$70-ROUND(Inputs!$B$24*Inputs!$B$28,0))*(C15-1)/11,0),IF(C15<=24,ROUND(Inputs!$B$70+(Inputs!$B$71-Inputs!$B$70)*(C15-12)/12,0),IF(C15<=36,ROUND(Inputs!$B$71+(Inputs!$B$72-Inputs!$B$71)*(C15-24)/12,0),IF(C15<=48,ROUND(Inputs!$B$72+(Inputs!$B$73-Inputs!$B$72)*(C15-36)/12,0),ROUND(Inputs!$B$73+(Inputs!$B$74-Inputs!$B$73)*MIN(C15-48,12)/12,0)))))))) -> 373 | E15: =IF(C15=0,0,IF(Inputs!$B$50=1,MIN(D15,MAX(0,Inputs!$B$57-Inputs!$B$54)),MIN(D15,Inputs!$B$57))) -> 373 | F15: =IF(AND(C15>=Inputs!$B$56,Inputs!$B$50=1),Inputs!$B$54,0) -> 0 | G15: =E15+F15 -> 373 | H15: =Inputs!$B$44*(1+Inputs!$B$20)^MAX(0,ROUNDUP(C15/12,0)-1) -> 223 | I15: =IF(C15=0,0,E15*H15+F15*Inputs!$B$55) -> 83179 | J15: =IF(C15=0,0,Inputs!$B$47) -> 6500 | K15: =I15+J15 -> 89679 | L15: =K15/(1+Inputs!$B$6) -> 75999.153 | M15: =(K15*Inputs!$B$49)/(1+Inputs!$B$6) -> 759.99153 | N15: =IF(C15=0,Inputs!$B$34,'Operating Costs'!$C$23*(1+Inputs!$B$19)^MAX(0,ROUNDUP(C15/12,0)-1)) -> 63913.729 | O15: =L15-M15-N15 -> 11325.432 | P15: {=INDEX(Financing!$J$17:$J$79,A15+1)} -> 0 | Q15: {=INDEX(Financing!$G$17:$G$79,A15+1)} -> 0 | R15: =IF(C15=0,0,Inputs!$B$18) -> 6813 | S15: =O15-R15-Q15 -> 4512.4322 | T15: =W14 -> 129497.31 | U15: =MAX(0,S15-T15) -> 0 | V15: =U15*Inputs!$B$17 -> 0 | W15: =MAX(0,T15-MAX(0,S15))+MAX(0,-S15) -> 124984.88 | X15: =O15-P15-V15 -> 11325.432 | Y15: =IF(A15=Inputs!$B$63,'Startup & Funding'!$B$16,0) -> 0 | Z15: =Z14+X15+Y15 -> 150442.85 | AA15: {=INDEX(Financing!$E$17:$E$79,A15+1)+INDEX(Financing!$I$17:$I$79,A15+1)} -> 1140000 | AB15: =AB14 -> 312.46637 | AC15: =AC14 -> 424.07501 | AD15: =IF(C15=1,"REOPEN",IF(A15=Inputs!$B$15,"DEBT START",IF(AND(C15>0,MOD(C15,12)=0),"YEAR END","")))
A16: =A15+1 -> 11 | B16: =IF(A16<Inputs!$B$27,"BUILD","OPEN") -> OPEN | C16: =IF(B16="OPEN",A16-Inputs!$B$27+1,0) -> 9 | D16: =IF(C16=0,0,MIN(Inputs!$B$25,IF(C16=1,ROUND(Inputs!$B$24*Inputs!$B$28,0),IF(C16<=12,ROUND(ROUND(Inputs!$B$24*Inputs!$B$28,0)+(Inputs!$B$70-ROUND(Inputs!$B$24*Inputs!$B$28,0))*(C16-1)/11,0),IF(C16<=24,ROUND(Inputs!$B$70+(Inputs!$B$71-Inputs!$B$70)*(C16-12)/12,0),IF(C16<=36,ROUND(Inputs!$B$71+(Inputs!$B$72-Inputs!$B$71)*(C16-24)/12,0),IF(C16<=48,ROUND(Inputs!$B$72+(Inputs!$B$73-Inputs!$B$72)*(C16-36)/12,0),ROUND(Inputs!$B$73+(Inputs!$B$74-Inputs!$B$73)*MIN(C16-48,12)/12,0)))))))) -> 392 | E16: =IF(C16=0,0,IF(Inputs!$B$50=1,MIN(D16,MAX(0,Inputs!$B$57-Inputs!$B$54)),MIN(D16,Inputs!$B$57))) -> 392 | F16: =IF(AND(C16>=Inputs!$B$56,Inputs!$B$50=1),Inputs!$B$54,0) -> 0 | G16: =E16+F16 -> 392 | H16: =Inputs!$B$44*(1+Inputs!$B$20)^MAX(0,ROUNDUP(C16/12,0)-1) -> 223 | I16: =IF(C16=0,0,E16*H16+F16*Inputs!$B$55) -> 87416 | J16: =IF(C16=0,0,Inputs!$B$47) -> 6500 | K16: =I16+J16 -> 93916 | L16: =K16/(1+Inputs!$B$6) -> 79589.831 | M16: =(K16*Inputs!$B$49)/(1+Inputs!$B$6) -> 795.89831 | N16: =IF(C16=0,Inputs!$B$34,'Operating Costs'!$C$23*(1+Inputs!$B$19)^MAX(0,ROUNDUP(C16/12,0)-1)) -> 63913.729 | O16: =L16-M16-N16 -> 14880.203 | P16: {=INDEX(Financing!$J$17:$J$79,A16+1)} -> 0 | Q16: {=INDEX(Financing!$G$17:$G$79,A16+1)} -> 0 | R16: =IF(C16=0,0,Inputs!$B$18) -> 6813 | S16: =O16-R16-Q16 -> 8067.2034 | T16: =W15 -> 124984.88 | U16: =MAX(0,S16-T16) -> 0 | V16: =U16*Inputs!$B$17 -> 0 | W16: =MAX(0,T16-MAX(0,S16))+MAX(0,-S16) -> 116917.68 | X16: =O16-P16-V16 -> 14880.203 | Y16: =IF(A16=Inputs!$B$63,'Startup & Funding'!$B$16,0) -> 0 | Z16: =Z15+X16+Y16 -> 165323.05 | AA16: {=INDEX(Financing!$E$17:$E$79,A16+1)+INDEX(Financing!$I$17:$I$79,A16+1)} -> 1140000 | AB16: =AB15 -> 312.46637 | AC16: =AC15 -> 424.07501 | AD16: =IF(C16=1,"REOPEN",IF(A16=Inputs!$B$15,"DEBT START",IF(AND(C16>0,MOD(C16,12)=0),"YEAR END","")))
A17: =A16+1 -> 12 | B17: =IF(A17<Inputs!$B$27,"BUILD","OPEN") -> OPEN | C17: =IF(B17="OPEN",A17-Inputs!$B$27+1,0) -> 10 | D17: =IF(C17=0,0,MIN(Inputs!$B$25,IF(C17=1,ROUND(Inputs!$B$24*Inputs!$B$28,0),IF(C17<=12,ROUND(ROUND(Inputs!$B$24*Inputs!$B$28,0)+(Inputs!$B$70-ROUND(Inputs!$B$24*Inputs!$B$28,0))*(C17-1)/11,0),IF(C17<=24,ROUND(Inputs!$B$70+(Inputs!$B$71-Inputs!$B$70)*(C17-12)/12,0),IF(C17<=36,ROUND(Inputs!$B$71+(Inputs!$B$72-Inputs!$B$71)*(C17-24)/12,0),IF(C17<=48,ROUND(Inputs!$B$72+(Inputs!$B$73-Inputs!$B$72)*(C17-36)/12,0),ROUND(Inputs!$B$73+(Inputs!$B$74-Inputs!$B$73)*MIN(C17-48,12)/12,0)))))))) -> 411 | E17: =IF(C17=0,0,IF(Inputs!$B$50=1,MIN(D17,MAX(0,Inputs!$B$57-Inputs!$B$54)),MIN(D17,Inputs!$B$57))) -> 411 | F17: =IF(AND(C17>=Inputs!$B$56,Inputs!$B$50=1),Inputs!$B$54,0) -> 0 | G17: =E17+F17 -> 411 | H17: =Inputs!$B$44*(1+Inputs!$B$20)^MAX(0,ROUNDUP(C17/12,0)-1) -> 223 | I17: =IF(C17=0,0,E17*H17+F17*Inputs!$B$55) -> 91653 | J17: =IF(C17=0,0,Inputs!$B$47) -> 6500 | K17: =I17+J17 -> 98153 | L17: =K17/(1+Inputs!$B$6) -> 83180.508 | M17: =(K17*Inputs!$B$49)/(1+Inputs!$B$6) -> 831.80508 | N17: =IF(C17=0,Inputs!$B$34,'Operating Costs'!$C$23*(1+Inputs!$B$19)^MAX(0,ROUNDUP(C17/12,0)-1)) -> 63913.729 | O17: =L17-M17-N17 -> 18434.975 | P17: {=INDEX(Financing!$J$17:$J$79,A17+1)} -> 20881.221 | Q17: {=INDEX(Financing!$G$17:$G$79,A17+1)} -> 3562.5 | R17: =IF(C17=0,0,Inputs!$B$18) -> 6813 | S17: =O17-R17-Q17 -> 8059.4746 | T17: =W16 -> 116917.68 | U17: =MAX(0,S17-T17) -> 0 | V17: =U17*Inputs!$B$17 -> 0 | W17: =MAX(0,T17-MAX(0,S17))+MAX(0,-S17) -> 108858.2 | X17: =O17-P17-V17 -> -2446.2462 | Y17: =IF(A17=Inputs!$B$63,'Startup & Funding'!$B$16,0) -> 0 | Z17: =Z16+X17+Y17 -> 162876.81 | AA17: {=INDEX(Financing!$E$17:$E$79,A17+1)+INDEX(Financing!$I$17:$I$79,A17+1)} -> 1122681.3 | AB17: =AB16 -> 312.46637 | AC17: =AC16 -> 424.07501 | AD17: =IF(C17=1,"REOPEN",IF(A17=Inputs!$B$15,"DEBT START",IF(AND(C17>0,MOD(C17,12)=0),"YEAR END",""))) -> DEBT START
... A67: =A66+1 -> 62 | B67: =IF(A67<Inputs!$B$27,"BUILD","OPEN") -> OPEN | C67: =IF(B67="OPEN",A67-Inputs!$B$27+1,0) -> 60 | D67: =IF(C67=0,0,MIN(Inputs!$B$25,IF(C67=1,ROUND(Inputs!$B$24*Inputs!$B$28,0),IF(C67<=12,ROUND(ROUND(Inputs!$B$24*Inputs!$B$28,0)+(Inputs!$B$70-ROUND(Inputs!$B$24*Inputs!$B$28,0))*(C67-1)/11,0),IF(C67<=24,ROUND(Inputs!$B$70+(Inputs!$B$71-Inputs!$B$70)*(C67-12)/12,0),IF(C67<=36,ROUND(Inputs!$B$71+(Inputs!$B$72-Inputs!$B$71)*(C67-24)/12,0),IF(C67<=48,ROUND(Inputs!$B$72+(Inputs!$B$73-Inputs!$B$72)*(C67-36)/12,0),ROUND(Inputs!$B$73+(Inputs!$B$74-Inputs!$B$73)*MIN(C67-48,12)/12,0)))))))) -> 850 | E67: =IF(C67=0,0,IF(Inputs!$B$50=1,MIN(D67,MAX(0,Inputs!$B$57-Inputs!$B$54)),MIN(D67,Inputs!$B$57))) -> 850 | F67: =IF(AND(C67>=Inputs!$B$56,Inputs!$B$50=1),Inputs!$B$54,0) -> 0 | G67: =E67+F67 -> 850 | H67: =Inputs!$B$44*(1+Inputs!$B$20)^MAX(0,ROUNDUP(C67/12,0)-1) -> 223 | I67: =IF(C67=0,0,E67*H67+F67*Inputs!$B$55) -> 189550 | J67: =IF(C67=0,0,Inputs!$B$47) -> 6500 | K67: =I67+J67 -> 196050 | L67: =K67/(1+Inputs!$B$6) -> 166144.07 | M67: =(K67*Inputs!$B$49)/(1+Inputs!$B$6) -> 1661.4407 | N67: =IF(C67=0,Inputs!$B$34,'Operating Costs'!$C$23*(1+Inputs!$B$19)^MAX(0,ROUNDUP(C67/12,0)-1)) -> 63913.729 | O67: =L67-M67-N67 -> 100568.9 | P67: {=INDEX(Financing!$J$17:$J$79,A67+1)} -> 20881.221 | Q67: {=INDEX(Financing!$G$17:$G$79,A67+1)} -> 653.8948 | R67: =IF(C67=0,0,Inputs!$B$18) -> 6813 | S67: =O67-R67-Q67 -> 93102.004 | T67: =W66 -> 0 | U67: =MAX(0,S67-T67) -> 93102.004 | V67: =U67*Inputs!$B$17 -> 21413.461 | W67: =MAX(0,T67-MAX(0,S67))+MAX(0,-S67) -> 0 | X67: =O67-P67-V67 -> 58274.217 | Y67: =IF(A67=Inputs!$B$63,'Startup & Funding'!$B$16,0) -> 0 | Z67: =Z66+X67+Y67 -> 1949791.8 | AA67: {=INDEX(Financing!$E$17:$E$79,A67+1)+INDEX(Financing!$I$17:$I$79,A67+1)} -> 184967.15 | AB67: =AB66 -> 312.46637 | AC67: =AC66 -> 424.07501 | AD67: =IF(C67=1,"REOPEN",IF(A67=Inputs!$B$15,"DEBT START",IF(AND(C67>0,MOD(C67,12)=0),"YEAR END",""))) -> YEAR END

Sheet 5-Year Summary
A1: 5 Operating Years - Target-Driven Plan
A2: Year 1 means the first 12 months AFTER reopening. The 3 build months are shown separately in the 63-month liquidity timeline.
A4: Metric | B4: Operating Year 1 | C4: Year 2 | D4: Year 3 | E4: Year 4 | F4: Year 5 | G4: Comment
A5: Avg total members incl. Moatza | B5: =AVERAGE('Monthly Base'!G8:G19) -> 344 | C5: =AVERAGE('Monthly Base'!G20:G31) -> 531.5 | D5: =AVERAGE('Monthly Base'!G32:G43) -> 667.75 | E5: =AVERAGE('Monthly Base'!G44:G55) -> 765.75 | F5: =AVERAGE('Monthly Base'!G56:G67) -> 827.16667 | G5: Target-driven monthly ramp
A6: End total members incl. Moatza | B6: ='Monthly Base'!G19 -> 450 | C6: ='Monthly Base'!G31 -> 600 | D6: ='Monthly Base'!G43 -> 725 | E6: ='Monthly Base'!G55 -> 800 | F6: ='Monthly Base'!G67 -> 850
A7: Gross billings | B7: =SUM('Monthly Base'!K8:K19) -> 998544 | C7: =SUM('Monthly Base'!K20:K31) -> 1500294 | D7: =SUM('Monthly Base'!K32:K43) -> 1864899 | E7: =SUM('Monthly Base'!K44:K55) -> 2127147 | F7: =SUM('Monthly Base'!K56:K67) -> 2291498 | G7: Incl VAT
A8: Net revenue ex VAT | B8: =SUM('Monthly Base'!L8:L19) -> 846223.73 | C8: =SUM('Monthly Base'!L20:L31) -> 1271435.6 | D8: =SUM('Monthly Base'!L32:L43) -> 1580422.9 | E8: =SUM('Monthly Base'!L44:L55) -> 1802666.9 | F8: =SUM('Monthly Base'!L56:L67) -> 1941947.5 | G8: P&L revenue
A9: EBITDA | B9: =SUM('Monthly Base'!O8:O19) -> 70796.746 | C9: =SUM('Monthly Base'!O20:O31) -> 491756.49 | D9: =SUM('Monthly Base'!O32:O43) -> 797653.91 | E9: =SUM('Monthly Base'!O44:O55) -> 1017675.5 | F9: =SUM('Monthly Base'!O56:O67) -> 1155563.2 | G9: Before financing/tax
A10: Total debt payments incl. semiannual lump-sum prepay | B10: =SUM('Owner Pay'!L24:L35)+SUM('Owner Pay'!U24:V35) -> 81666.476 | C10: =SUM('Owner Pay'!L36:L47)+SUM('Owner Pay'!U36:V47) -> 424218.24 | D10: =SUM('Owner Pay'!L48:L59)+SUM('Owner Pay'!U48:V59) -> 636626.7 | E10: =SUM('Owner Pay'!L60:L71)+SUM('Owner Pay'!U60:V71) -> 58610.857 | F10: =SUM('Owner Pay'!L72:L83)+SUM('Owner Pay'!U72:V83) -> 0 | G10: Grace ends during Year 1 because build consumes grace
A11: Corporate tax — debt-first plan | B11: =SUM('Owner Pay'!R24:R35) -> 0 | C11: =SUM('Owner Pay'!R36:R47) -> 67538.255 | D11: =SUM('Owner Pay'!R48:R59) -> 161027.21 | E11: =SUM('Owner Pay'!R60:R71) -> 215261.49 | F11: =SUM('Owner Pay'!R72:R83) -> 246975.66 | G11: Loss-carryforward model
A12: Net cash after debt, tax & owner salaries | B12: =SUM('Owner Pay'!D24:D35)-B10-B11-SUM('Owner Pay'!P24:P35) -> -10869.73 | C12: =SUM('Owner Pay'!D36:D47)-C10-C11-SUM('Owner Pay'!P36:P47) -> 0 | D12: =SUM('Owner Pay'!D48:D59)-D10-D11-SUM('Owner Pay'!P48:P59) -> 2.910383e-10 | E12: =SUM('Owner Pay'!D60:D71)-E10-E11-SUM('Owner Pay'!P60:P71) -> 743803.18 | F12: =SUM('Owner Pay'!D72:D83)-F10-F11-SUM('Owner Pay'!P72:P83) -> 908587.57 | G12: After debt + tax
A13: Contractual DSCR | B13: =IF(SUM('Owner Pay'!L24:L35)=0,0,B9/SUM('Owner Pay'!L24:L35)) -> 1.1301502 | C13: =IF(SUM('Owner Pay'!L36:L47)=0,0,C9/SUM('Owner Pay'!L36:L47)) -> 1.9625149 | D13: =IF(SUM('Owner Pay'!L48:L59)=0,0,D9/SUM('Owner Pay'!L48:L59)) -> 3.1832985 | E13: =IF(SUM('Owner Pay'!L60:L71)=0,0,E9/SUM('Owner Pay'!L60:L71)) -> 42.403147 | F13: =IF(SUM('Owner Pay'!L72:L83)=0,0,F9/SUM('Owner Pay'!L72:L83)) -> 0 | G13: EBITDA / debt service
A14: Year-end company cash — no distributions | B14: ='Owner Pay'!Z35 -> 150000 | C14: ='Owner Pay'!Z47 -> 150000 | D14: ='Owner Pay'!Z59 -> 150000 | E14: ='Owner Pay'!Z71 -> 893803.18 | F14: ='Owner Pay'!Z83 -> 1802390.8 | G14: Includes startup headroom + build VAT refund
A15: Year-end debt balance | B15: ='Owner Pay'!Y35 -> 1068862.7 | C15: ='Owner Pay'!Y47 -> 679457.94 | D15: ='Owner Pay'!Y59 -> 58610.857 | E15: ='Owner Pay'!Y71 -> 0 | F15: ='Owner Pay'!Y83 -> 0
A16: Cumulative net cash after debt/tax/salaries | B16: =B12 -> -10869.73 | C16: =B16+C12 -> -10869.73 | D16: =C16+D12 -> -10869.73 | E16: =D16+E12 -> 732933.45 | F16: =E16+F12 -> 1641521 | G16: Excludes one-time VAT refund/headroom
A17: Partner 1 50% of year-end distributable cash | B17: =IF(B15=0,MAX(0,B14-Inputs!$B$80)*Inputs!$B$7,0) -> 0 | C17: =IF(C15=0,MAX(0,C14-Inputs!$B$80)*Inputs!$B$7,0) -> 0 | D17: =IF(D15=0,MAX(0,D14-Inputs!$B$80)*Inputs!$B$7,0) -> 0 | E17: =IF(E15=0,MAX(0,E14-Inputs!$B$80)*Inputs!$B$7,0) -> 371901.59 | F17: =IF(F15=0,MAX(0,F14-Inputs!$B$80)*Inputs!$B$7,0) -> 826195.38 | G17: Not take-home
A18: Partner 2 50% of year-end distributable cash | B18: =IF(B15=0,MAX(0,B14-Inputs!$B$80)*Inputs!$B$8,0) -> 0 | C18: =IF(C15=0,MAX(0,C14-Inputs!$B$80)*Inputs!$B$8,0) -> 0 | D18: =IF(D15=0,MAX(0,D14-Inputs!$B$80)*Inputs!$B$8,0) -> 0 | E18: =IF(E15=0,MAX(0,E14-Inputs!$B$80)*Inputs!$B$8,0) -> 371901.59 | F18: =IF(F15=0,MAX(0,F14-Inputs!$B$80)*Inputs!$B$8,0) -> 826195.38 | G18: Not take-home
A19: Owner gross salaries paid | B19: =SUM('Owner Pay'!N24:O35) -> 0 | C19: =SUM('Owner Pay'!N36:O47) -> 0 | D19: =SUM('Owner Pay'!N48:O59) -> 0 | E19: =SUM('Owner Pay'!N60:O71) -> 0 | F19: =SUM('Owner Pay'!N72:O83) -> 0 | I19: Metric | J19: Y1 | K19: Y2 | L19: Y3 | M19: Y4 | N19: Y5
A20: Company owner payroll cost | B20: =SUM('Owner Pay'!P24:P35) -> 0 | C20: =SUM('Owner Pay'!P36:P47) -> 0 | D20: =SUM('Owner Pay'!P48:P59) -> 0 | E20: =SUM('Owner Pay'!P60:P71) -> 0 | F20: =SUM('Owner Pay'!P72:P83) -> 0 | I20: EBITDA | J20: =B9 -> 70796.746 | K20: =C9 -> 491756.49 | L20: =D9 -> 797653.91 | M20: =E9 -> 1017675.5 | N20: =F9 -> 1155563.2
A21: Key thresholds | I21: Debt service | J21: =B10 -> 81666.476 | K21: =C10 -> 424218.24 | L21: =D10 -> 636626.7 | M21: =E10 -> 58610.857 | N21: =F10 -> 0
A22: Metric | B22: Result | C22: Interpretation | I22: Pre-owner cash | J22: =B12 -> -10869.73 | K22: =C12 -> 0 | L22: =D12 -> 2.910383e-10 | M22: =E12 -> 743803.18 | N22: =F12 -> 908587.57
A23: Reopening members | B23: =ROUND(Inputs!$B$24*Inputs!$B$28,0) -> 238 | C23: 75% of 317
A24: Operating break-even members | B24: ='Monthly Base'!AB5 -> 312.46637 | C24: Before debt / tax
A25: Post-debt break-even members | B25: ='Monthly Base'!AC5 -> 424.07501 | C25: After loan payments start
A26: Operating month payments begin | B26: =Financing!$D$13 -> 10 | C26: Build months consume grace
A27: Operating month base reaches post-debt break-even | B27: =MIN(60,IFERROR(MATCH(B25,'Monthly Base'!G8:G67,0),MATCH(B25,'Monthly Base'!G8:G67,1)+1)) -> 11 | C27: Based on the target-driven membership ramp
A28: Operating month reaches Year-1 member target | B28: 12 | C28: By design: end of operating Year 1
A29: Operating month reaches 600 members | B29: =MIN(60,IFERROR(MATCH(600,'Monthly Base'!G8:G67,0),MATCH(600,'Monthly Base'!G8:G67,1)+1)) -> 24 | C29: Growth milestone
A30: Minimum cash balance in full timeline | B30: {=MIN(MIN('Owner Pay'!Z21:Z83),INDEX('Owner Pay'!F21:F83,Inputs!$B$63+1)+INDEX('Owner Pay'!D21:D83,Inputs!$B$63+1))} -> 8936.0014 | C30: Primary runway test incl. pre-refund low
A31: Debt-free operating month | B31: ='Owner Pay'!B9 -> 42 | C31: Semiannual debt-sweep plan
A32: Owner salaries start operating month | B32: ='Owner Pay'!B10 -> OFF | C32: Month after all debt is repaid
A33: Interest saved vs scheduled amortization | B33: ='Owner Pay'!B13 -> 48787.14 | C33: Estimated interest avoided
A34: Contractual monthly debt service eliminated | B34: ='Owner Pay'!B14 -> 20881.221 | C34: Cash flow freed once debt is gone
A35: Company monthly owner payroll after debt | B35: ='Owner Pay'!B12 -> 24000 | C35: Includes employer load
A36: Year 5 cash available for distribution | B36: ='Owner Pay'!B16 -> 1652390.8 | C36: Above reserve; not automatically distributed
A37: Partner 1 50% if fully distributed | B37: ='Owner Pay'!B17 -> 826195.38 | C37: Before personal/dividend tax
A38: Partner 2 50% if fully distributed | B38: ='Owner Pay'!B16*Inputs!$B$8 -> 826195.38 | C38: Before personal/dividend tax
A39: Debt-sweep cash reserve target | B39: =Inputs!$B$80 -> 150000 | C39: Kept in company for resilience / peace of mind
A40: Months debt eliminated early | B40: ='Owner Pay'!B18 -> 27 | C40: Vs scheduled maturity

Sheet Owner Pay
A1: Semiannual Debt-Sweep Capital Allocation & Owner Pay
A2: Current base case: debt-max policy with equal 50/50 owner salaries after debt. Both partners work in the business; Hodaya is staff. See Salary Scenarios for alternatives.
A4: Metric | B4: Result | C4: Interpretation
A5: Debt-sweep cash reserve target | B5: =Inputs!$B$80 -> 150000 | C5: Cash deliberately retained in the company.
A6: Excess cash used at each sweep | B6: =Inputs!$B$81 -> 1 | C6: Semiannual lump-sum review; Prime debt first.
A7: Debt repayment priority | B7: =Inputs!$B$83 -> Loan B (Prime) → Loan A (0%) | C7: Prime debt first, then 0% debt.
A8: Debt-free timeline month | B8: {=IFERROR(INDEX(A21:A83,MATCH(0,Y21:Y83,0)),"Beyond model")} -> 44 | C8: Timeline includes the renovation months.
A9: Debt-free operating month | B9: {=IFERROR(INDEX(C21:C83,MATCH(0,Y21:Y83,0)),"Beyond model")} -> 42 | C9: Month after reopening when total debt reaches zero.
A10: Salaries start operating month | B10: =IF(Inputs!$B$84=1,IF(ISNUMBER(B9),B9+1,"Beyond model"),"OFF") -> OFF | C10: Starts the month after all debt is gone.
A11: Post-debt owner gross salaries / month | B11: =Inputs!$B$85+Inputs!$B$86 -> 20000 | C11: Current base: ₪10k gross per partner, equal 50/50.
A12: Company owner payroll cost / month | B12: =B11*(1+Inputs!$B$66) -> 24000 | C12: Includes modeled 20% employer load.
A13: Interest saved vs scheduled amortization | B13: =SUM(Financing!$G$17:$G$79)-SUM(J21:J83) -> 48787.14 | C13: Estimated Loan B interest avoided by accelerated payoff.
A14: Contractual monthly debt service eliminated | B14: =Financing!$D$10 -> 20881.221 | C14: Monthly contractual payment freed once debt is gone.
A15: Year 5 company cash — no distributions | B15: =Z83 -> 1802390.8 | C15: Cash remains in company unless owners choose a distribution.
A16: Year 5 cash available for distribution | B16: =IF(Y83=0,MAX(0,Z83-Inputs!$B$80),0) -> 1652390.8 | C16: Above the reserve floor only; no automatic distribution modeled.
